ERROR:app:Exception on /logout [POST]
Traceback (most recent call last):
  File "/home/runner/workspace/.pythonlibs/lib/python3.11/site-packages/flask/app.py", line 917, in full_dispatch_request
    rv = self.dispatch_request()
         ^^^^^^^^^^^^^^^^^^^^^^^
  File "/home/runner/workspace/.pythonlibs/lib/python3.11/site-packages/flask/app.py", line 902, in dispatch_request
    return self.ensure_sync(self.view_functions[rule.endpoint])(**view_args)  # type: ignore[no-any-return]
           ^^^^^^^^^^^^^^^^^^^^^^^^^^^^^^^^^^^^^^^^^^^^^^^^^^^^^^^^^^^^^^^^^
  File "/home/runner/workspace/.pythonlibs/lib/python3.11/site-packages/flask_jwt_extended/view_decorators.py", line 167, in decorator
    verify_jwt_in_request(
  File "/home/runner/workspace/.pythonlibs/lib/python3.11/site-packages/flask_jwt_extended/view_decorators.py", line 94, in verify_jwt_in_request
    jwt_data, jwt_header, jwt_location = _decode_jwt_from_request(
                                         ^^^^^^^^^^^^^^^^^^^^^^^^^
  File "/home/runner/workspace/.pythonlibs/lib/python3.11/site-packages/flask_jwt_extended/view_decorators.py", line 368, in _decode_jwt_from_request
    verify_token_not_blocklisted(jwt_header, decoded_token)
  File "/home/runner/workspace/.pythonlibs/lib/python3.11/site-packages/flask_jwt_extended/internal_utils.py", line 59, in verify_token_not_blocklisted
    raise RevokedTokenError(jwt_header, jwt_data)
flask_jwt_extended.exceptions.RevokedTokenError: Token has been revoked

During handling of the above exception, another exception occurred:

Traceback (most recent call last):
  File "/home/runner/workspace/.pythonlibs/lib/python3.11/site-packages/flask/app.py", line 1511, in wsgi_app
    response = self.full_dispatch_request()
               ^^^^^^^^^^^^^^^^^^^^^^^^^^^^
  File "/home/runner/workspace/.pythonlibs/lib/python3.11/site-packages/flask/app.py", line 919, in full_dispatch_request
    rv = self.handle_user_exception(e)
         ^^^^^^^^^^^^^^^^^^^^^^^^^^^^^
  File "/home/runner/workspace/.pythonlibs/lib/python3.11/site-packages/flask_cors/extension.py", line 176, in wrapped_function
    return cors_after_request(app.make_response(f(*args, **kwargs)))
                              ^^^^^^^^^^^^^^^^^^^^^^^^^^^^^^^^^^^^^
  File "/home/runner/workspace/.pythonlibs/lib/python3.11/site-packages/flask/app.py", line 1204, in make_response
    raise TypeError(
TypeError: The view function did not return a valid response tuple. The tuple must have the form (body, status, headers), (body, status), or (body, headers).