sycopg2.errors.UniqueViolation: duplicate key value violates unique constraint "game_score_game_id_key"
DETAIL:  Key (game_id)=(medium-cc6f0f0f-df01-4962-93ef-f462886aaa39) already exists.


The above exception was the direct cause of the following exception:

Traceback (most recent call last):
  File "/home/runner/workspace/app/services/game_state.py", line 275, in abandon_game
    db.session.commit()
  File "/home/runner/workspace/.pythonlibs/lib/python3.11/site-packages/sqlalchemy/orm/scoping.py", line 599, in commit
    return self._proxied.commit()
           ^^^^^^^^^^^^^^^^^^^^^^
  File "/home/runner/workspace/.pythonlibs/lib/python3.11/site-packages/sqlalchemy/orm/session.py", line 2032, in commit
    trans.commit(_to_root=True)
  File "<string>", line 2, in commit
  File "/home/runner/workspace/.pythonlibs/lib/python3.11/site-packages/sqlalchemy/orm/state_changes.py", line 139, in _go
    ret_value = fn(self, *arg, **kw)
                ^^^^^^^^^^^^^^^^^^^^
  File "/home/runner/workspace/.pythonlibs/lib/python3.11/site-packages/sqlalchemy/orm/session.py", line 1313, in commit
    self._prepare_impl()
  File "<string>", line 2, in _prepare_impl
  File "/home/runner/workspace/.pythonlibs/lib/python3.11/site-packages/sqlalchemy/orm/state_changes.py", line 139, in _go
    ret_value = fn(self, *arg, **kw)
                ^^^^^^^^^^^^^^^^^^^^
  File "/home/runner/workspace/.pythonlibs/lib/python3.11/site-packages/sqlalchemy/orm/session.py", line 1288, in _prepare_impl
    self.session.flush()
  File "/home/runner/workspace/.pythonlibs/lib/python3.11/site-packages/sqlalchemy/orm/session.py", line 4353, in flush
    self._flush(objects)
  File "/home/runner/workspace/.pythonlibs/lib/python3.11/site-packages/sqlalchemy/orm/session.py", line 4488, in _flush
    with util.safe_reraise():
  File "/home/runner/workspace/.pythonlibs/lib/python3.11/site-packages/sqlalchemy/util/langhelpers.py", line 146, in __exit__
    raise exc_value.with_traceback(exc_tb)
  File "/home/runner/workspace/.pythonlibs/lib/python3.11/site-packages/sqlalchemy/orm/session.py", line 4449, in _flush
    flush_context.execute()
  File "/home/runner/workspace/.pythonlibs/lib/python3.11/site-packages/sqlalchemy/orm/unitofwork.py", line 466, in execute
    rec.execute(self)
  File "/home/runner/workspace/.pythonlibs/lib/python3.11/site-packages/sqlalchemy/orm/unitofwork.py", line 642, in execute
    util.preloaded.orm_persistence.save_obj(
  File "/home/runner/workspace/.pythonlibs/lib/python3.11/site-packages/sqlalchemy/orm/persistence.py", line 93, in save_obj
    _emit_insert_statements(
  File "/home/runner/workspace/.pythonlibs/lib/python3.11/site-packages/sqlalchemy/orm/persistence.py", line 1233, in _emit_insert_statements
    result = connection.execute(
             ^^^^^^^^^^^^^^^^^^^
  File "/home/runner/workspace/.pythonlibs/lib/python3.11/site-packages/sqlalchemy/engine/base.py", line 1416, in execute
    return meth(
           ^^^^^
  File "/home/runner/workspace/.pythonlibs/lib/python3.11/site-packages/sqlalchemy/sql/elements.py", line 523, in _execute_on_connection
    return connection._execute_clauseelement(
           ^^^^^^^^^^^^^^^^^^^^^^^^^^^^^^^^^^
  File "/home/runner/workspace/.pythonlibs/lib/python3.11/site-packages/sqlalchemy/engine/base.py", line 1638, in _execute_clauseelement
    ret = self._execute_context(
          ^^^^^^^^^^^^^^^^^^^^^^
  File "/home/runner/workspace/.pythonlibs/lib/python3.11/site-packages/sqlalchemy/engine/base.py", line 1843, in _execute_context
    return self._exec_single_context(
           ^^^^^^^^^^^^^^^^^^^^^^^^^^
  File "/home/runner/workspace/.pythonlibs/lib/python3.11/site-packages/sqlalchemy/engine/base.py", line 1983, in _exec_single_context
    self._handle_dbapi_exception(
  File "/home/runner/workspace/.pythonlibs/lib/python3.11/site-packages/sqlalchemy/engine/base.py", line 2352, in _handle_dbapi_exception
    raise sqlalchemy_exception.with_traceback(exc_info[2]) from e
  File "/home/runner/workspace/.pythonlibs/lib/python3.11/site-packages/sqlalchemy/engine/base.py", line 1964, in _exec_single_context
    self.dialect.do_execute(
  File "/home/runner/workspace/.pythonlibs/lib/python3.11/site-packages/sqlalchemy/engine/default.py", line 942, in do_execute
    cursor.execute(statement, parameters)
sqlalchemy.exc.IntegrityError: (psycopg2.errors.UniqueViolation) duplicate key value violates unique constraint "game_score_game_id_key"
DETAIL:  Key (game_id)=(medium-cc6f0f0f-df01-4962-93ef-f462886aaa39) already exists.

[SQL: INSERT INTO game_score (user_id, game_id, score, mistakes, time_taken, game_type, challenge_date, completed, created_at) VALUES (%(user_id)s, %(game_id)s, %(score)s, %(mistakes)s, %(time_taken)s, %(game_type)s, %(challenge_date)s, %(completed)s, %(created_at)s) RETURNING game_score.id]
[parameters: {'user_id': '4da22d94-7761-4ada-81ee-0bf8acb35b85', 'game_id': 'medium-cc6f0f0f-df01-4962-93ef-f462886aaa39', 'score': 0, 'mistakes': 5, 'time_taken': 21, 'game_type': 'regular', 'challenge_date': '2025-04-22', 'completed': False, 'created_at': datetime.datetime(2025, 4, 22, 21, 35, 56, 502141)}]
(Background on this error at: https://sqlalche.me/e/20/gkpj)
INFO:app.routes.game:Found existing regular game for user 4da22d94-7761-4ada-81ee-0bf8acb35b85 - abandoning
ERROR:app.routes.game:Error abandoning existing game for user 4da22d94-7761-4ada-81ee-0bf8acb35b85: (psycopg2.errors.UniqueViolation) duplicate key value violates unique constraint "game_score_game_id_key"
DETAIL:  Key (game_id)=(medium-cc6f0f0f-df01-4962-93ef-f462886aaa39) already exists.

[SQL: INSERT INTO game_score (user_id, game_id, score, mistakes, time_taken, game_type, challenge_date, completed, created_at) VALUES (%(user_id)s, %(game_id)s, %(score)s, %(mistakes)s, %(time_taken)s, %(game_type)s, %(challenge_date)s, %(completed)s, %(created_at)s) RETURNING game_score.id]